newTests/complex_6.in
40
o
9 B 100 ARNC 1892 861
13 B 101 BAC^N 1947 944
16 S 102 AGM^F 1143 73
36 B 103 BFS 1004 541
32 B 104 ADCT 1643 798
30 B 105 BABA 1706 714
39 S 106 AMG 1484 622
15 S 107 A 1060 791
38 S 108 ARLO 859 435
18 B 109 BEN 627 58
23 B 110 AU 1680 46
14 S 111 BCC 737 772
8 S 112 AFGB 1738 922
9 S 113 AB 1094 907
21 S 114 AMN 1204 544
9 B 115 ATH^B 1647 749
36 B 116 BIP 1577 672
11 S 117 AFT 824 829
13 B 118 AQNA 1816 770
39 S 119 ARES 859 299
31 B 120 AGRO 134 753
25 B 121 BBAR 1577 429
37 S 122 BMA 1075 287
20 S 123 BHG 1121 446
23 S 124 ADX 1581 689
27 S 125 AMTD 1121 800
3 B 126 BALY 1678 565
25 S 127 BKD 462 777
21 S 128 AGS 341 422
2 B 129 BLE 860 31
8 B 130 BEP 1327 846
15 S 131 AHT^I 980 451
26 S 132 ABR^D 337 213
18 B 133 AMT 585 930
2 B 134 BFAC 1213 553
1 S 135 ABR 332 478
12 S 136 BHK 175 321
18 B 137 BHE 1118 377
35 S 138 AJG 1274 103
11 S 139 ASA 1089 841
27 S 140 BEKE 1808 289
38 B 141 AIU 1062 139
29 S 142 APH 988 962
22 S 143 AHT^F 856 719
22 S 144 BC 545 657
36 S 145 AESC 1262 51
7 B 146 BKE 833 658
17 S 147 BAK 1523 307
29 S 148 BJ 177 937
30 S 149 AIZ 655 559
16 B 150 BMA 1328 11
9 S 151 AVYA 374 268
12 B 152 BHG 770 167
15 B 153 AMPX 1273 38
33 B 154 AMH 963 827
4 B 155 AFG 1802 752
20 B 156 AGI 878 918
5 S 157 BABA 1550 437
37 B 158 BML^G 1560 851
26 S 159 AOMR 1882 352
38 S 160 AWP 334 603
13 S 161 ALK 693 639
2 S 162 BLDR 1976 479
25 B 163 AVD 1721 843
31 B 164 BHE 1392 667
18 B 165 AAN 1402 783
9 S 166 ASGI 1334 856
33 B 167 AGO 265 837
2 B 168 AXAC 1545 252
34 S 169 AGM^D 1547 512
17 S 170 ADX 105 925
31 S 171 ARGD 1762 393
17 B 172 AZEK 684 545
28 B 173 BC^A 281 250
30 S 174 BAC^Q 1798 524
1 S 175 BBD 1485 427
11 B 176 ASB 556 530
25 S 177 ACHR 1979 395
7 B 178 BDX 553 130
18 S 179 APRN 1760 626
22 B 180 BAH 127 401
3 B 181 BEST 1577 409
11 S 182 AIU 729 678
35 S 183 AYX 724 920
31 B 184 BABA 501 676
6 S 185 BAC^O 1670 881
39 S 186 AGX 504 488
12 B 187 ABG 135 804
13 S 188 BAC^E 519 421
3 B 189 BAC^E 1950 775
38 B 190 BBVA 237 909
20 S 191 BAK 368 585
34 B 192 ALC 1832 707
14 B 193 BC 240 206
21 S 194 AMH 1611 272
23 S 195 ASAI 1719 110
24 S 196 BHC 1881 656
4 S 197 BG 1504 733
33 S 198 AGO 884 217
32 B 199 ADCT 899 108
24 S 200 ALL^H 158 788
9 S 201 AYI 173 647
8 S 202 ATH^E 264 889
20 B 203 BE 1701 502
20 S 204 BBUC 1422 754
2 S 205 BCAT 253 92
33 B 206 BCS 1863 477
31 B 207 ALK 990 855
28 B 208 BEPH 1094 220
12 S 209 BFAC 481 495
11 B 210 AOMR 1488 10
5 S 211 ACRE 1777 831
29 B 212 APRN 1495 414
35 B 213 BKU 484 573
20 S 214 ARE 410 339
13 S 215 BERY 1823 890
21 S 216 BAC 181 794
31 S 217 BIPC 1373 388
20 B 218 AEL 400 150
0 S 219 ATEK 609 598
24 B 220 BHC 444 443
32 S 221 BIO 803 773
35 B 222 BHLB 1639 985
24 S 223 AG 1256 517
10 B 224 AXR 1802 964
25 B 225 APO 617 447
10 S 226 AMAM 593 704
39 S 227 BDN 633 716
7 S 228 BLE 1031 954
2 B 229 BMAC 638 542
17 B 230 AMX 710 45
33 S 231 AKA 1369 740
19 B 232 BML^G 448 456
37 B 233 BLW 1365 372
20 B 234 ALB 435 385
9 S 235 ACR 1125 446
34 S 236 BGR 881 345
3 B 237 AHL^E 1620 760
25 B 238 ARI 639 365
37 B 239 AI 566 938
13 B 240 AHT^G 618 449
16 S 241 BIO/B 296 592
3 S 242 AVNT 1930 98
21 B 243 ATUS 484 942
27 S 244 AVYA 1384 880
15 S 245 AGS 1885 498
12 B 246 ATI 1233 908
13 B 247 ADCT 168 717
21 B 248 BHC 1020 491
37 B 249 BLX 573 339
26 B 250 APCA 1773 723
36 S 251 BDX 1799 673
34 S 252 ARMK 1642 483
38 S 253 AWK 1466 963
1 B 254 BEP 1280 101
17 B 255 BK 444 206
1 B 256 AQN 1741 841
30 B 257 AMX 1605 278
33 B 258 AIG^A 1948 476
22 S 259 AP 662 355
15 B 260 BC^C 1281 903
25 S 261 BIP^B 1512 25
37 S 262 BHV 1396 575
21 B 263 BEPC 1124 509
10 S 264 APH 1962 917
19 S 265 BDC 1070 751
28 B 266 AXS^E 558 499
37 B 267 APLE 510 490
21 B 268 AVYA 1490 622
29 S 269 BBW 1529 832
5 S 270 BML^G 922 200
14 S 271 B 953 33
14 S 272 ATAQ 1300 910
18 B 273 BDN 247 599
21 B 274 ALB 1519 803
31 B 275 APAM 1759 842
10 S 276 AMR 286 295
35 S 277 AWK 1730 475
15 S 278 ASH 287 74
18 B 279 AXS 197 394
22 S 280 BHR 481 802
12 S 281 AJX 688 269
3 S 282 BCX 1241 941
8 S 283 AMWL 1840 800
19 B 284 ARE 577 810
11 B 285 AEG 706 897
30 B 286 AYI 361 284
31 S 287 ASA 1655 483
19 B 288 AYX 936 767
26 B 289 APH 806 889
13 B 290 AIO 401 554
9 B 291 AEL 1444 910
20 S 292 BAC^K 386 134
8 B 293 BAC^O 255 292
15 B 294 ARCO 1286 649
28 S 295 AAM^A 147 116
36 B 296 AJG 839 27
12 S 297 BBN 800 51
19 S 298 AVD 314 980
27 S 299 AZRE 726 350
3 S 300 BAC^B 691 817
7 S 301 ATTO 591 598
5 S 302 BCH 206 293
16 S 303 BFLY 230 838
5 B 304 AA 1013 528
29 B 305 AFGD 1478 615
23 S 306 ABR 1081 201
10 S 307 ACP^A 556 913
20 B 308 ALTG^A 414 674
24 S 309 AGM 1676 939
16 S 310 ASX 1648 504
19 B 311 BDX 1943 908
35 S 312 BHC 172 931
28 S 313 BAC^P 1127 476
36 S 314 BFS^D 947 720
29 S 315 APD 1617 101
10 S 316 BFAM 988 108
27 S 317 AFTR 1320 213
10 S 318 AAP 1061 665
20 B 319 AG 166 396
26 S 320 BCAT 1715 628
17 B 321 ABM 1002 608
38 S 322 BIO/B 1025 303
25 B 323 AHT^I 1757 339
17 B 324 AUB 425 541
27 S 325 AMX 514 742
2 S 326 ABR 1249 234
5 B 327 BLW 1855 362
30 S 328 AEVA 856 747
31 S 329 BERY 414 845
32 B 330 BALL 1936 883
0 B 331 ALCC 123 905
34 B 332 APTV^A 1078 845
19 B 333 ABEV 666 575
7 S 334 ATKR 1575 362
31 S 335 AEL 489 68
26 B 336 BHR^B 652 929
2 B 337 ATHM 748 151
23 S 338 AHH 836 955
19 B 339 AHT^G 746 787
30 B 340 BCAT 1393 671
15 B 341 BML^G 1115 14
0 S 342 AKO/B 1489 557
8 S 343 AEL^B 1220 561
28 S 344 APGB 1275 48
34 B 345 BAM 1712 922
2 S 346 ARCH 1774 965
6 B 347 BKI 461 986
37 B 348 ATH^B 1117 410
17 S 349 BAC^Q 1516 762
4 S 350 BKT 1376 550
21 B 351 ASG 1594 500
2 S 352 ARES 402 430
21 S 353 ARES 1813 20
8 S 354 ALL^G 645 523
28 S 355 BHC 1809 694
21 B 356 ATIP 1609 615
27 S 357 BAM 141 812
27 S 358 ATCO 1434 639
26 S 359 ABBV 223 643
14 B 360 BBDC 1928 162
0 B 361 BAC^K 1063 447
17 B 362 BIP^A 884 624
18 B 363 AB 105 952
11 B 364 AHH^A 1066 604
5 S 365 ACN 1516 361
5 B 366 BF/A 187 937
23 B 367 ABG 212 960
24 B 368 BANC 1303 183
35 B 369 BBWI 1101 75
8 S 370 BBLN 841 634
11 S 371 BBDO 1436 718
33 S 372 ATEK 131 898
17 B 373 AZO 387 168
26 S 374 AIN 1258 131
35 S 375 AUY 803 414
34 B 376 ALLY 394 151
1 S 377 AEO 677 741
27 S 378 AAM^B 1540 363
6 B 379 BIPI 1124 384
4 S 380 ALK 1850 177
34 S 381 ALK 839 705
27 S 382 AON 1243 810
8 S 383 AGI 397 349
21 S 384 B 745 338
38 B 385 ALCC 1759 217
9 S 386 AVNS 134 928
6 S 387 ALV 1136 904
19 B 388 AQUA 384 578
29 S 389 AMPS 1680 65
31 B 390 AKO/A 1145 271
4 B 391 BFZ 1327 606
39 S 392 BMEZ 129 324
4 B 393 BHR 1308 881
17 S 394 ATKR 1363 174
26 S 395 AHH 475 98
9 S 396 ABM 549 552
6 B 397 AQNB 1786 395
6 B 398 AMH^G 1029 108
7 S 399 ATH^A 964 64
7 S 400 AEL 1947 191
14 S 401 BHIL 964 406
27 B 402 AWI 387 141
12 S 403 BAM 466 295
7 B 404 AEL 1037 561
35 B 405 BCO 1486 700
25 S 406 ATCO^I 267 546
19 B 407 BALY 214 912
22 S 408 BFLY 1757 463
3 B 409 BML^H 589 315
13 B 410 AWP 1759 806
39 B 411 APLE 1152 941
0 S 412 BDX 704 535
13 B 413 BML^H 772 857
16 S 414 BBAR 763 975
20 B 415 ACCO 241 426
13 S 416 BEPH 1149 380
10 B 417 BDC 680 843
24 B 418 BLK 1332 13
17 B 419 AGM^G 1674 957
16 B 420 BBLN 1795 870
28 B 421 ABBV 433 345
36 S 422 AGRO 1047 824
9 S 423 AWK 724 542
10 S 424 BCX 490 851
35 S 425 ARE 622 26
22 B 426 AVA 1700 854
0 S 427 BCC 570 427
18 S 428 ALL^B 121 774
21 B 429 ARIS 1598 686
32 S 430 ASAN 1549 213
31 S 431 AGCO 741 872
7 S 432 BKD 1662 532
1 B 433 AAN 127 292
9 S 434 AYI 569 149
6 B 435 BCSF 1660 759
24 S 436 AP 313 923
10 S 437 ATEK 1024 216
13 S 438 BAC^E 627 175
38 S 439 AZEK 1049 84
25 B 440 BBDO 940 982
0 S 441 AEG 1011 688
8 B 442 AKO/A 165 969
36 S 443 ADX 1812 577
29 S 444 AUB 1321 587
28 B 445 BHE 1163 199
22 S 446 AIF 493 360
19 B 447 AHT 1168 641
1 S 448 AGM^C 1236 426
20 B 449 AFTR 1140 217
19 B 450 BBAR 1438 93
13 S 451 ABT 1621 390
2 B 452 BBLN 492 501
0 B 453 BAC^N 306 660
0 B 454 ASIX 1501 107
23 B 455 AES 1864 99
3 B 456 AUB^A 716 964
37 S 457 APTV 344 412
28 B 458 AAM^A 1838 404
2 B 459 AQNB 796 550
4 S 460 AU 587 478
3 S 461 BAC^P 1858 916
27 B 462 AIZ 1854 565
31 B 463 BHR^D 330 777
35 B 464 ATEN 1015 934
19 B 465 ACP^A 1189 742
39 B 466 ADCT 483 501
