newTests/medium_0.in
4
o
3 S 101 AAC 1438 452
3 B 102 A 796 221
3 B 103 AAM 1873 334
3 B 104 AAO 1118 220
3 C 102
3 B 107 AAIE 977 648
3 S 109 AAO 405 822
3 C 104
0 S 112 AAID 1538 154
0 C 112
0 B 114 AA 1606 484
3 B 115 AAM 272 164
1 S 116 AAIC 490 57
0 S 117 AAN 1511 413
3 C 101
1 S 119 AAIE 1212 643
0 B 120 AAC 143 675
x
