newTests/medium_14.in
4
o
3 B 101 AAIN 849 667
3 C 101
1 S 103 AAID 1064 113
1 B 104 AAO 1372 97
3 C 101
1 C 104
3 S 107 AA 157 666
3 C 101
3 S 110 AAO 1467 547
2 B 111 AA 1760 515
2 S 112 AAIE 1730 377
2 B 113 AAO 1994 938
0 S 114 AAID 607 552
2 C 111
2 B 116 AAC 1102 537
0 S 117 AAM 1066 600
2 S 118 AAM 480 22
0 C 117
2 S 120 AAM 757 146
3 C 110
3 C 107
1 B 123 AAID 1401 508
0 S 124 AAID 947 405
1 S 125 AAC 160 562
2 S 126 AAIN 737 357
1 C 104
0 C 124
1 C 103
2 C 126
1 C 123
2 B 132 A 1465 53
2 C 111
2 S 134 AAIE 1120 970
0 C 114
2 B 136 AAIE 1635 524
1 C 123
1 S 138 AA 382 739
1 B 139 AAIE 1132 672
1 S 140 AAO 590 719
1 B 141 AAIE 1230 533
2 S 142 A 968 923
1 B 143 AAIC 1786 105
3 S 144 AAN 1766 794
0 C 114
3 B 146 AAO 1114 669
2 S 147 AAN 1620 78
3 B 148 A 1233 936
1 C 139
0 S 150 AA 1367 626
3 S 151 AAIN 1124 544
0 S 152 AAM 1428 344
2 C 147
1 C 143
1 C 138
2 C 111
2 B 157 AAC 1121 845
3 S 158 AAO 1699 158
1 B 159 AAID 194 100
0 B 160 AAC 260 221
2 S 161 A 1035 595
3 C 110
3 B 163 AAID 1045 971
0 C 160
0 B 165 AAO 1208 900
0 B 166 AAIE 1078 786
3 C 107
2 B 168 AAO 1261 85
1 S 169 AAIN 1408 260
0 C 166
1 B 171 AAIN 1587 389
2 B 172 AAIN 1261 143
1 S 173 AAIC 870 448
3 B 174 AAIN 933 693
2 S 175 AAIE 558 326
3 B 176 AAIN 470 573
3 B 177 AAM 1586 457
1 B 178 AAIC 314 468
1 C 140
3 C 144
0 B 181 AA 1476 486
0 S 182 AAO 1160 392
0 S 183 A 711 726
2 S 184 AAO 155 627
1 C 143
3 B 186 AAM 1446 335
3 S 187 AAN 1482 773
0 S 188 AAIE 839 345
2 B 189 AA 452 941
1 S 190 AAIE 316 175
3 S 191 AAM 740 11
1 S 192 AAC 682 404
2 C 118
0 C 117
2 C 112
2 C 113
3 B 197 AAN 923 66
2 S 198 AAIN 258 128
0 B 199 AAO 927 1000
3 C 144
3 B 201 AAN 1457 418
1 S 202 AAO 819 763
2 C 172
0 S 204 A 214 565
1 S 205 AAO 358 894
2 B 206 AAIE 678 622
0 B 207 AAC 1757 687
1 B 208 AAIN 1457 165
1 B 209 AA 1878 257
3 B 210 AAN 755 408
2 S 211 AAM 480 391
2 C 132
1 S 213 AAN 1930 41
1 S 214 AAC 448 744
2 B 215 AAO 1591 846
3 B 216 AAC 1056 657
2 S 217 AAO 1997 463
0 B 218 AAIE 1971 964
2 B 219 AAO 498 497
0 B 220 AAIN 1175 866
2 C 132
1 B 222 AAM 1984 807
0 C 181
0 C 207
2 C 113
1 C 169
1 S 227 A 276 582
3 B 228 AAIN 1367 711
2 C 132
3 S 230 AAM 1243 356
2 S 231 AAC 1151 111
2 S 232 AAC 1466 950
0 C 207
1 B 234 AAN 554 754
3 B 235 A 234 13
3 B 236 AAIE 1717 239
0 S 237 AAIC 633 874
1 S 238 AAC 1821 810
0 C 199
1 C 192
1 B 241 AAIC 1013 392
3 B 242 AAM 454 205
0 B 243 AAID 909 152
3 B 244 AAIC 1613 481
0 B 245 AAIC 713 50
1 S 246 AAIE 392 542
1 B 247 AAIC 1949 550
1 B 248 AAO 987 570
1 B 249 AAIE 384 28
0 S 250 AAIN 1829 898
0 S 251 AAO 1555 535
0 B 252 AAM 1182 713
0 S 253 AAIE 534 686
1 C 246
3 C 244
1 C 247
3 C 148
x
