newTests/medium_16.in
4
o
2 B 101 AAC 964 749
1 B 103 AAN 569 30
3 S 105 AAIC 487 106
3 B 106 AAO 1854 754
3 B 107 AAIC 1641 423
0 S 108 AAM 1041 359
0 B 109 AA 1309 900
1 S 110 AA 1333 495
1 C 110
3 S 112 AAIC 1501 625
1 C 103
1 C 103
3 C 105
1 B 116 AAIC 1287 913
1 B 117 AAO 1799 929
0 B 118 AAM 1939 159
1 S 119 AAIC 1906 315
1 B 120 AAIC 110 866
1 C 103
2 S 122 AAO 128 550
1 B 123 AA 1852 919
1 S 124 AAIE 1408 397
1 C 123
0 C 108
1 C 110
0 C 108
1 B 129 AAO 685 343
2 C 101
3 B 131 AA 281 341
2 B 132 AA 1221 243
1 C 124
2 B 134 AAC 1027 160
2 C 122
3 S 136 AAO 1070 939
2 S 137 AAIE 1538 797
0 C 109
3 S 139 AA 1401 416
x
