newTests/medium_19.in
4
o
2 S 101 AAO 865 284
1 S 102 AAO 1651 476
3 B 103 AAC 592 779
3 C 103
2 B 105 AAN 278 144
0 S 107 AAIE 1719 236
0 C 107
0 B 109 AAC 1751 772
0 C 109
3 S 111 AA 981 548
0 B 112 AAIE 1475 177
1 C 102
3 S 114 AAO 1887 14
2 B 115 AAIE 1312 59
2 S 116 AAID 394 775
3 B 117 A 567 84
1 C 102
2 S 119 A 1956 269
0 B 120 A 1977 376
3 S 121 AAC 1790 354
1 C 102
1 S 123 AAM 1373 513
1 C 123
3 B 125 AAIE 1855 895
1 S 126 AAIE 547 857
2 S 127 A 902 105
3 B 128 AAIE 425 607
2 C 127
2 B 130 A 1417 426
1 S 131 AAIN 1932 677
2 B 132 AAM 1297 736
0 S 133 AAIN 1118 427
2 C 119
3 C 125
1 C 102
2 B 137 AAN 121 892
0 B 138 AAC 1219 840
0 S 139 AAIN 464 939
0 S 140 AA 1351 490
2 B 141 AAM 278 91
3 B 142 AAIE 1227 217
0 S 143 AAIN 1502 582
0 C 143
2 C 130
2 C 119
0 B 147 AAM 1259 303
0 C 107
0 B 149 AA 372 489
1 C 131
3 S 151 AAC 1286 701
2 C 137
2 B 153 AAC 1761 421
0 S 154 AAO 1958 834
2 B 155 AAIN 244 655
3 C 125
1 B 157 AAN 1176 935
0 S 158 AAN 1807 38
1 C 131
3 B 160 A 406 200
3 B 161 AA 863 544
2 C 141
1 C 102
2 B 164 AAO 911 634
3 B 165 A 1869 198
2 S 166 AAC 680 242
2 B 167 AA 1119 613
0 S 168 AAC 208 611
3 S 169 AAIN 570 671
0 B 170 AAIC 282 232
2 B 171 AAM 1657 359
2 B 172 AAN 451 300
0 B 173 AA 1108 831
2 B 174 AAM 1480 601
3 C 117
0 B 176 AAIN 404 994
1 B 177 AAN 915 234
1 S 178 A 1711 375
1 S 179 AAIE 1811 24
0 C 173
2 B 181 AAM 1855 847
3 B 182 AA 1938 61
2 S 183 AAIC 1813 192
0 S 184 A 618 134
1 B 185 AAC 1726 739
1 S 186 AAC 1176 427
0 B 187 AAO 1171 264
3 B 188 AAID 798 247
3 C 151
3 C 160
1 B 191 AA 490 527
2 C 101
2 C 141
0 C 176
3 B 195 AAIE 1170 706
0 B 196 AAM 165 210
0 C 187
0 B 198 AAID 1956 307
0 C 109
2 C 166
1 C 102
1 C 102
1 B 203 AAIE 1102 590
2 B 204 AAN 1993 224
3 B 205 AA 449 215
3 S 206 AAO 1546 951
1 B 207 AAM 1013 835
2 C 101
1 C 179
0 C 196
0 S 211 AAIE 1806 661
0 B 212 AAIN 1955 733
1 B 213 AAIC 1718 981
0 C 184
3 B 215 AAIC 1705 778
2 B 216 AA 901 677
0 B 217 AAID 369 355
0 C 168
1 B 219 A 1192 24
1 S 220 AAO 1075 294
0 C 154
0 S 222 AAN 314 582
3 S 223 AAO 881 823
2 S 224 AA 1386 643
3 C 206
1 B 226 AAM 760 211
3 S 227 AAIN 1922 934
2 C 119
3 S 229 A 1052 908
2 S 230 AAM 1969 864
3 B 231 A 768 587
1 S 232 AAIC 1318 104
0 C 133
1 B 234 AAID 1234 568
2 C 172
1 S 236 AAM 484 775
2 S 237 AAIC 1279 165
2 C 204
3 S 239 AAM 1490 191
2 S 240 AAIN 477 948
3 B 241 AAN 1979 492
2 B 242 AAID 768 202
2 B 243 AAM 214 55
1 B 244 AAIN 1883 206
2 B 245 AAIC 1205 841
2 S 246 AAC 117 613
0 C 217
0 C 138
2 S 249 AAO 358 648
2 S 250 AAM 416 59
2 C 116
2 B 252 A 1755 370
2 C 105
3 S 254 AAID 1366 114
2 C 183
2 B 256 AAN 525 732
2 S 257 AAC 1328 247
1 C 123
1 C 213
0 C 212
1 C 191
0 B 262 AAIC 347 452
0 S 263 AAO 924 230
1 C 203
0 S 265 A 699 86
1 B 266 A 172 889
1 B 267 AAIC 1792 25
1 B 268 AAIE 1653 413
2 B 269 AAIE 818 380
2 S 270 AAN 1363 676
3 C 254
2 C 167
0 S 273 AAIE 765 677
3 C 239
0 C 184
0 C 120
0 S 277 AAC 301 297
0 S 278 AAO 435 689
3 B 279 AAIE 701 458
1 C 244
2 B 281 AAN 419 251
3 B 282 AAC 1623 244
0 S 283 AAO 1548 896
3 C 165
2 S 285 AAID 1594 870
0 C 263
2 S 287 AAIN 1258 28
2 S 288 AAIN 1965 908
3 B 289 AAID 1836 42
3 C 125
0 B 291 AAC 949 323
2 B 292 AAC 1149 665
1 S 293 AAID 1790 813
3 C 279
0 B 295 AAO 181 486
x
