newTests/medium_2.in
4
o
1 B 101 AAC 886 38
1 B 102 AAO 1580 231
0 B 103 AA 1632 614
1 C 102
2 B 107 AAO 1215 262
1 C 101
1 B 109 AAN 471 265
2 B 110 AAC 904 119
0 C 103
2 B 112 AAID 629 316
0 B 113 AAIE 738 250
2 C 110
2 S 115 AAN 1463 975
1 C 109
1 S 117 AAID 1980 306
1 S 118 AAID 959 433
0 C 103
0 B 120 AAIE 232 129
2 S 121 AAIC 367 148
0 C 113
0 S 123 AAM 1116 145
3 S 124 AA 438 50
3 B 125 AAIE 1564 557
3 S 126 AAM 1391 936
3 S 127 AAIC 460 337
1 S 128 AAN 1340 280
3 S 129 AAIE 1386 848
3 S 130 AA 1981 365
1 B 131 AA 1940 516
2 B 132 AAO 472 703
2 S 133 AAIN 599 584
3 B 134 AA 376 512
2 C 112
3 B 136 AAID 603 804
3 S 137 AAIN 1775 667
0 S 138 AAIC 344 594
0 B 139 AAID 973 194
3 C 124
0 C 120
0 B 142 AAM 849 652
3 B 143 AAIE 591 584
3 B 144 AAIC 426 496
3 S 145 AAC 358 357
2 B 146 AAM 1726 395
0 B 147 AAIN 1240 529
3 B 148 AAN 1530 449
3 S 149 AAIC 218 806
1 B 150 AAIC 1384 655
1 B 151 AAC 1357 318
1 S 152 AAIC 600 226
3 B 153 AAN 344 323
3 B 154 AA 1931 16
1 B 155 AAO 510 766
2 S 156 AAN 814 204
3 S 157 AAID 507 502
2 S 158 A 745 117
0 B 159 AAID 602 940
2 B 160 AAIN 381 617
2 C 156
3 C 136
2 C 112
2 B 164 AA 1643 776
3 C 130
3 S 166 AAID 1930 903
3 S 167 AAID 1001 767
0 B 168 AAID 259 438
1 S 169 AA 811 120
3 B 170 AAIN 1071 849
3 B 171 AAIE 1649 463
0 C 139
0 B 173 AAIN 702 620
0 C 120
3 S 175 AAIE 592 583
2 C 133
0 B 177 AAIE 1228 897
2 C 146
0 S 179 AAC 680 939
2 B 180 A 947 619
2 B 181 A 890 495
3 S 182 AAID 414 985
3 C 127
3 B 184 AAM 1420 997
1 C 101
3 B 186 AAIC 1545 927
0 S 187 AAO 1275 267
2 C 146
3 C 149
3 S 190 AAO 1077 355
1 C 109
1 S 192 AAM 256 337
3 C 153
1 C 128
1 C 102
2 B 196 AAIC 1678 46
3 C 144
1 C 117
0 C 103
1 C 117
0 C 159
2 C 164
0 C 139
0 S 204 AAC 851 596
2 C 112
2 B 206 AA 143 616
0 B 207 AAIC 557 840
2 B 208 AA 840 73
1 C 128
0 B 210 AAIE 1172 566
1 S 211 AAIN 1004 168
2 B 212 AAC 1795 305
2 B 213 AAO 196 341
0 C 207
2 B 215 AAIN 224 41
0 C 177
1 S 217 AAID 1629 541
0 C 139
1 B 219 AAID 1522 698
3 S 220 AAN 1929 400
3 B 221 AAIE 1517 343
3 C 171
0 B 223 AAC 1375 979
3 C 143
2 B 225 AAM 1673 843
3 S 226 AA 1345 25
0 C 113
3 C 220
3 B 229 AAC 1395 562
2 C 180
1 S 231 A 850 524
3 B 232 AAO 710 230
0 S 233 AAN 1456 452
1 C 128
2 S 235 AAN 1507 297
0 S 236 AAID 434 467
3 B 237 AAM 1854 176
2 C 156
0 S 239 AAC 609 968
2 C 133
2 B 241 AA 1245 551
1 B 242 A 897 173
3 S 243 AAIN 836 659
1 S 244 AAO 1290 792
3 S 245 AAO 996 284
2 C 132
2 C 160
0 B 248 AAN 1870 468
3 S 249 AAIE 222 341
0 C 204
2 B 251 A 1444 122
2 S 252 AAID 1968 893
3 B 253 A 188 178
2 S 254 AAIC 116 54
1 S 255 AAID 1756 233
3 C 134
0 S 257 AAIC 1001 315
2 B 258 AA 954 605
0 C 120
3 S 260 AA 833 600
1 B 261 A 1284 83
3 S 262 AAO 329 127
3 C 232
1 S 264 AAIN 1766 505
3 S 265 A 484 343
2 S 266 AAIE 1721 624
2 B 267 A 1504 763
3 C 144
3 B 269 AAIN 881 597
3 C 125
3 B 271 AAIE 840 147
0 C 120
3 S 273 AAN 1572 775
0 S 274 AA 553 554
0 S 275 AAIN 942 909
1 B 276 AA 254 95
1 C 211
1 C 131
0 S 279 AAID 898 789
3 B 280 AAN 1682 486
2 C 110
3 S 282 AAM 1985 651
1 B 283 AAN 1683 48
0 C 236
2 B 285 AAM 1550 516
2 B 286 AAC 1252 688
3 S 287 AAID 1414 355
1 C 152
x
