newTests/medium_21.in
4
o
1 B 101 AAIE 543 563
2 B 103 AAIE 916 866
3 S 104 AAO 377 856
3 C 104
3 C 104
1 C 101
2 B 108 AAIN 137 168
1 S 109 A 159 664
2 C 108
3 B 113 AAC 1274 514
1 S 114 AAM 1277 98
1 C 114
2 S 116 AAC 685 576
3 B 118 AA 1578 811
2 C 103
2 B 120 AAN 414 516
1 S 121 AAN 1092 341
2 B 122 AAID 1691 183
3 C 104
1 B 124 AAID 258 731
1 S 125 AAIC 544 868
2 B 126 AAID 558 488
3 B 127 AAN 767 808
3 B 128 AA 1089 478
1 C 121
3 S 130 AA 1577 380
2 B 131 AAM 1802 742
0 B 132 AA 854 697
0 B 133 AAIC 1854 237
0 C 132
0 S 135 A 105 903
3 S 136 AAIC 1380 453
3 S 137 A 315 625
3 B 138 AAN 604 680
1 B 139 AAIN 174 623
3 S 140 AA 1716 651
0 B 141 AAN 1898 314
1 S 142 AAID 1866 52
3 S 143 AAIE 1949 29
0 B 144 AA 627 27
3 B 145 AAM 523 158
3 C 127
0 C 144
2 S 148 AAN 917 626
1 S 149 AAO 150 660
2 C 116
0 S 151 AAO 1166 257
3 C 138
1 C 139
1 S 154 A 1303 391
0 C 141
3 B 156 AAID 1429 900
0 B 157 AAID 974 883
0 B 158 AAIC 1262 872
3 S 159 AAIE 1968 659
3 B 160 AAN 2000 35
1 B 161 AAM 139 648
0 S 162 AAIC 1950 296
0 S 163 AAC 209 437
0 C 151
3 B 165 AAC 416 816
2 B 166 AAM 804 446
2 B 167 AAN 490 989
3 C 118
1 S 169 AAO 1145 369
0 B 170 AA 1158 16
0 C 135
0 S 172 AAC 210 444
3 B 173 AAIE 1721 227
2 C 116
1 B 175 AAC 1921 181
0 S 176 AAIN 689 964
3 S 177 AAIE 1453 637
2 B 178 AA 1295 421
3 C 113
0 B 180 A 1941 387
0 S 181 AA 1095 101
1 B 182 AAIN 1598 348
2 C 116
0 B 184 AAIN 1325 121
3 C 173
0 C 181
1 C 125
1 B 188 AAIN 724 572
3 S 189 A 1578 161
0 S 190 AAN 1499 558
2 C 120
2 B 192 AAM 1860 774
3 B 193 AAO 265 640
1 C 125
2 C 122
1 S 196 AAID 1639 605
0 S 197 AAN 1658 296
2 C 167
1 B 199 AAC 396 586
1 C 169
0 B 201 AAIC 1346 490
3 C 127
3 B 203 AAID 186 946
2 S 204 AAM 218 997
0 B 205 AAIE 897 524
3 B 206 AAO 1217 106
0 B 207 AAIC 1663 795
1 B 208 AAM 274 758
2 S 209 AA 723 478
0 B 210 AA 1762 494
1 S 211 AA 1413 615
3 B 212 AAID 1419 615
2 B 213 AAC 1561 997
0 C 184
0 C 201
1 B 216 AAIC 1306 680
2 C 166
3 B 218 AAID 741 254
3 C 193
2 S 220 AAN 1671 770
x
