newTests/medium_28.in
4
o
2 B 104 AAIC 258 421
1 S 105 AAIC 1605 174
1 B 106 AAIN 357 946
0 S 108 AAM 733 861
1 C 106
2 S 110 AAM 1708 455
3 B 112 AA 1670 823
2 C 104
3 S 114 AAIN 1394 816
2 S 115 AAC 937 725
3 S 116 AAO 1595 473
3 C 116
1 S 118 AAIE 227 248
3 C 114
0 B 120 AA 541 213
2 C 110
0 C 120
1 B 123 AAO 1245 686
1 S 124 AAN 1677 63
1 B 125 AAIE 1677 846
0 S 126 AAO 1008 999
2 B 127 AAIN 839 838
2 C 104
2 C 115
0 S 130 AAN 1356 557
1 S 131 A 1381 592
1 S 132 AAIC 1706 488
3 S 133 AAIE 1281 692
1 B 134 AAIE 812 247
1 B 135 AAC 1487 723
x
