newTests/medium_36.in
4
o
0 S 101 AAIC 1014 980
0 B 102 AAIN 1994 970
3 S 103 A 402 693
0 B 104 AAO 1007 256
0 B 105 AAN 477 176
0 C 102
0 S 107 AAIE 432 172
0 C 104
0 S 109 A 836 537
1 B 111 AAIE 1688 485
1 B 112 AA 1244 707
3 B 113 AAC 922 409
1 B 114 AAIN 1522 407
3 S 115 AAM 1795 801
1 B 116 AAO 1085 186
3 S 117 AAC 923 645
1 C 114
1 S 119 AAIN 366 459
1 C 112
3 C 115
0 C 104
0 B 123 AAIC 356 482
3 C 113
1 B 125 AAO 332 422
0 B 126 AAIC 1525 56
1 B 127 AAM 1436 68
0 B 128 AAM 1696 508
1 C 125
1 C 125
3 S 131 AAIN 1215 644
1 B 132 AAC 1669 989
0 C 107
0 B 134 AAIN 1626 31
0 B 135 AAO 386 292
0 C 128
1 S 137 AAIC 1326 343
2 B 138 AA 1088 15
3 B 139 AA 378 869
3 B 140 AAIE 1340 743
3 S 141 AAO 1871 891
1 S 142 AAM 1658 73
0 C 126
3 B 144 AAIC 1744 529
1 S 145 AAID 510 779
2 S 146 AAIN 410 619
1 C 145
3 C 144
1 C 114
1 B 150 AAIC 1034 172
3 C 115
1 B 152 AAID 933 932
2 C 146
2 C 146
1 B 155 AAO 162 958
0 B 156 AAIE 1845 40
2 S 157 AAM 1069 723
1 B 158 AA 731 480
2 B 159 AA 591 347
3 B 160 AAM 1069 347
0 B 161 AAIE 1214 716
1 B 162 AAID 707 365
3 B 163 AAO 429 796
0 B 164 AAC 876 877
1 S 165 AA 502 118
0 B 166 AAO 1564 748
3 C 131
0 S 168 AAIC 604 955
2 B 169 AAM 533 795
1 B 170 AA 1478 664
3 C 117
2 S 172 AAO 1338 76
1 S 173 A 970 513
1 C 111
2 B 175 AAIN 1427 758
3 C 160
0 S 177 AAIN 992 644
2 B 178 AAID 1038 480
1 S 179 AAID 336 73
0 B 180 AA 290 25
3 B 181 AAN 1291 824
0 C 105
0 B 183 AAN 901 484
1 S 184 AAM 1945 70
0 B 185 AAIE 1278 822
1 B 186 AAID 1712 951
3 S 187 AAM 962 905
2 C 178
2 C 169
0 S 190 AAID 1096 106
3 C 131
0 S 192 AAID 1125 128
0 S 193 AAID 1410 204
1 S 194 AA 795 222
1 C 125
3 B 196 AAID 887 555
0 C 156
3 C 196
1 B 199 AAIE 870 469
3 B 200 AAIE 1110 441
1 S 201 AAC 272 296
0 S 202 AAC 290 926
2 S 203 AAN 980 179
0 C 192
0 S 205 AAIC 1238 791
3 C 163
0 C 180
2 S 208 AAIE 1379 773
0 C 109
3 C 117
0 B 211 AAN 850 350
1 S 212 AAO 888 985
2 B 213 AAIN 1588 690
0 S 214 AAIC 1906 116
1 S 215 AAM 900 13
1 B 216 AAIC 673 877
2 S 217 AAID 1439 827
3 S 218 AAIN 635 465
0 S 219 AA 501 162
0 B 220 AAIN 1880 670
1 C 142
0 B 222 AAN 1456 558
2 S 223 AAM 1388 715
3 S 224 AAIN 1208 309
3 S 225 AAIC 370 86
2 B 226 AAO 632 597
0 B 227 AAO 1077 346
3 C 181
3 B 229 AAC 1098 104
1 C 150
1 S 231 AA 347 730
1 B 232 AAIC 174 609
3 C 139
2 S 234 A 347 348
3 S 235 AAO 646 478
3 B 236 AAC 1064 786
3 C 224
0 B 238 A 779 118
0 C 192
3 B 240 AAIE 1093 62
1 B 241 A 989 430
2 S 242 AAIC 1876 945
3 S 243 AAC 1222 288
1 B 244 AAO 1942 959
x
